Traceback (most recent call last):
  File "/home/cpebiosustain_gmail_com/miniforge3/envs/proteusAI/lib/python3.8/site-packages/urllib3/connection.py", line 199, in _new_conn
    sock = connection.create_connection(
  File "/home/cpebiosustain_gmail_com/miniforge3/envs/proteusAI/lib/python3.8/site-packages/urllib3/util/connection.py", line 85, in create_connection
    raise err
  File "/home/cpebiosustain_gmail_com/miniforge3/envs/proteusAI/lib/python3.8/site-packages/urllib3/util/connection.py", line 73, in create_connection
    sock.connect(sa)
socket.timeout: timed out

The above exception was the direct cause of the following exception:

Traceback (most recent call last):
  File "/home/cpebiosustain_gmail_com/miniforge3/envs/proteusAI/lib/python3.8/site-packages/urllib3/connectionpool.py", line 789, in urlopen
    response = self._make_request(
  File "/home/cpebiosustain_gmail_com/miniforge3/envs/proteusAI/lib/python3.8/site-packages/urllib3/connectionpool.py", line 495, in _make_request
    conn.request(
  File "/home/cpebiosustain_gmail_com/miniforge3/envs/proteusAI/lib/python3.8/site-packages/urllib3/connection.py", line 441, in request
    self.endheaders()
  File "/home/cpebiosustain_gmail_com/miniforge3/envs/proteusAI/lib/python3.8/http/client.py", line 1251, in endheaders
    self._send_output(message_body, encode_chunked=encode_chunked)
  File "/home/cpebiosustain_gmail_com/miniforge3/envs/proteusAI/lib/python3.8/http/client.py", line 1011, in _send_output
    self.send(msg)
  File "/home/cpebiosustain_gmail_com/miniforge3/envs/proteusAI/lib/python3.8/http/client.py", line 951, in send
    self.connect()
  File "/home/cpebiosustain_gmail_com/miniforge3/envs/proteusAI/lib/python3.8/site-packages/urllib3/connection.py", line 279, in connect
    self.sock = self._new_conn()
  File "/home/cpebiosustain_gmail_com/miniforge3/envs/proteusAI/lib/python3.8/site-packages/urllib3/connection.py", line 208, in _new_conn
    raise ConnectTimeoutError(
urllib3.exceptions.ConnectTimeoutError: (<urllib3.connection.HTTPConnection object at 0x1534b341b250>, 'Connection to 34.13.195.239 timed out. (connect timeout=120)')

The above exception was the direct cause of the following exception:

Traceback (most recent call last):
  File "/home/cpebiosustain_gmail_com/miniforge3/envs/proteusAI/lib/python3.8/site-packages/requests/adapters.py", line 667, in send
    resp = conn.urlopen(
  File "/home/cpebiosustain_gmail_com/miniforge3/envs/proteusAI/lib/python3.8/site-packages/urllib3/connectionpool.py", line 873, in urlopen
    return self.urlopen(
  File "/home/cpebiosustain_gmail_com/miniforge3/envs/proteusAI/lib/python3.8/site-packages/urllib3/connectionpool.py", line 873, in urlopen
    return self.urlopen(
  File "/home/cpebiosustain_gmail_com/miniforge3/envs/proteusAI/lib/python3.8/site-packages/urllib3/connectionpool.py", line 873, in urlopen
    return self.urlopen(
  [Previous line repeated 2 more times]
  File "/home/cpebiosustain_gmail_com/miniforge3/envs/proteusAI/lib/python3.8/site-packages/urllib3/connectionpool.py", line 843, in urlopen
    retries = retries.increment(
  File "/home/cpebiosustain_gmail_com/miniforge3/envs/proteusAI/lib/python3.8/site-packages/urllib3/util/retry.py", line 519, in increment
    raise MaxRetryError(_pool, url, reason) from reason  # type: ignore[arg-type]
urllib3.exceptions.MaxRetryError: HTTPConnectionPool(host='34.13.195.239', port=5000): Max retries exceeded with url: /api/2.0/mlflow/experiments/get-by-name?experiment_name=test_experiment (Caused by ConnectTimeoutError(<urllib3.connection.HTTPConnection object at 0x1534b341b250>, 'Connection to 34.13.195.239 timed out. (connect timeout=120)'))

During handling of the above exception, another exception occurred:

Traceback (most recent call last):
  File "/home/cpebiosustain_gmail_com/miniforge3/envs/proteusAI/lib/python3.8/site-packages/mlflow/utils/rest_utils.py", line 189, in http_request
    return _get_http_response_with_retries(
  File "/home/cpebiosustain_gmail_com/miniforge3/envs/proteusAI/lib/python3.8/site-packages/mlflow/utils/request_utils.py", line 237, in _get_http_response_with_retries
    return session.request(method, url, allow_redirects=allow_redirects, **kwargs)
  File "/home/cpebiosustain_gmail_com/miniforge3/envs/proteusAI/lib/python3.8/site-packages/requests/sessions.py", line 589, in request
    resp = self.send(prep, **send_kwargs)
  File "/home/cpebiosustain_gmail_com/miniforge3/envs/proteusAI/lib/python3.8/site-packages/requests/sessions.py", line 703, in send
    r = adapter.send(request, **kwargs)
  File "/home/cpebiosustain_gmail_com/miniforge3/envs/proteusAI/lib/python3.8/site-packages/requests/adapters.py", line 688, in send
    raise ConnectTimeout(e, request=request)
requests.exceptions.ConnectTimeout: HTTPConnectionPool(host='34.13.195.239', port=5000): Max retries exceeded with url: /api/2.0/mlflow/experiments/get-by-name?experiment_name=test_experiment (Caused by ConnectTimeoutError(<urllib3.connection.HTTPConnection object at 0x1534b341b250>, 'Connection to 34.13.195.239 timed out. (connect timeout=120)'))

The above exception was the direct cause of the following exception:

Traceback (most recent call last):
  File "src/training/mlflow_test.py", line 13, in <module>
    mlflow.set_experiment('test_experiment')
  File "/home/cpebiosustain_gmail_com/miniforge3/envs/proteusAI/lib/python3.8/site-packages/mlflow/tracking/fluent.py", line 145, in set_experiment
    experiment = client.get_experiment_by_name(experiment_name)
  File "/home/cpebiosustain_gmail_com/miniforge3/envs/proteusAI/lib/python3.8/site-packages/mlflow/tracking/client.py", line 1256, in get_experiment_by_name
    return self._tracking_client.get_experiment_by_name(name)
  File "/home/cpebiosustain_gmail_com/miniforge3/envs/proteusAI/lib/python3.8/site-packages/mlflow/tracking/_tracking_service/client.py", line 501, in get_experiment_by_name
    return self.store.get_experiment_by_name(name)
  File "/home/cpebiosustain_gmail_com/miniforge3/envs/proteusAI/lib/python3.8/site-packages/mlflow/store/tracking/rest_store.py", line 519, in get_experiment_by_name
    response_proto = self._call_endpoint(GetExperimentByName, req_body)
  File "/home/cpebiosustain_gmail_com/miniforge3/envs/proteusAI/lib/python3.8/site-packages/mlflow/store/tracking/rest_store.py", line 82, in _call_endpoint
    return call_endpoint(self.get_host_creds(), endpoint, method, json_body, response_proto)
  File "/home/cpebiosustain_gmail_com/miniforge3/envs/proteusAI/lib/python3.8/site-packages/mlflow/utils/rest_utils.py", line 365, in call_endpoint
    response = http_request(**call_kwargs)
  File "/home/cpebiosustain_gmail_com/miniforge3/envs/proteusAI/lib/python3.8/site-packages/mlflow/utils/rest_utils.py", line 204, in http_request
    raise MlflowException(
mlflow.exceptions.MlflowException: API request to http://34.13.195.239:5000/api/2.0/mlflow/experiments/get-by-name failed with timeout exception HTTPConnectionPool(host='34.13.195.239', port=5000): Max retries exceeded with url: /api/2.0/mlflow/experiments/get-by-name?experiment_name=test_experiment (Caused by ConnectTimeoutError(<urllib3.connection.HTTPConnection object at 0x1534b341b250>, 'Connection to 34.13.195.239 timed out. (connect timeout=120)')). To increase the timeout, set the environment variable MLFLOW_HTTP_REQUEST_TIMEOUT (default: 120, type: int) to a larger value.
hpcslurmkd-computenodeset-0
